<?xml version="1.0" ?>
<robot name="robotarm" xmlns:xacro="http://www.ros.org/wiki/xacro">

  <xacro:include filename="$(find robotarm_description)/urdf/materials.xacro" />
  <!-- <xacro:include filename="$(find robotarm_description)/urdf/robotarm.trans" /> -->
  <xacro:include filename="$(find robotarm_description)/urdf/robotarm.gazebo" />

  <link name="world"/>
  <joint name="world_to_base_link=" type="fixed">
     <parent link="world"/>
     <child link="base_link"/>
  </joint>

  <link name="base_link">
    <inertial>
      <origin xyz="3.211366342053439e-17 -6.749204728423484e-16 0.09710635778016181" rpy="0 0 0"/>
      <mass value="0.954218401189586"/>
      <inertia ixx="0.0" iyy="0.0" izz="0.0" ixy="0.0" iyz="0.0" ixz="0.0"/>
    </inertial>
    <visual>
      <origin xyz="0 0 0" rpy="0 0 0"/>
      <geometry>
        <mesh filename="package://robotarm_description/meshes/base_link.stl" scale="0.001 0.001 0.001"/>
      </geometry>
      <material name="steel_satin"/>
    </visual>
    <collision>
      <origin xyz="0 0 0" rpy="0 0 0"/>
      <geometry>
        <mesh filename="package://robotarm_description/meshes/base_link.stl" scale="0.001 0.001 0.001"/>
      </geometry>
    </collision>
  </link>

  <link name="arm_v2_1">
    <inertial>
      <origin xyz="2.86641694438031e-12 7.1651962032025505e-12 0.11542328726383948" rpy="0 0 0"/>
      <mass value="0.701474550782814"/>
      <inertia ixx="0.0" iyy="0.0" izz="0.0" ixy="-0.0" iyz="0.0" ixz="0.0"/>
    </inertial>
    <visual>
      <origin xyz="0.0 -0.0 -0.0" rpy="0 0 0"/>
      <geometry>
        <mesh filename="package://robotarm_description/meshes/arm_v2_1.stl" scale="0.001 0.001 0.001"/>
      </geometry>
      <material name="steel_satin"/>
    </visual>
    <collision>
      <origin xyz="0.0 -0.0 -0.0" rpy="0 0 0"/>
      <geometry>
        <mesh filename="package://robotarm_description/meshes/arm_v2_1.stl" scale="0.001 0.001 0.001"/>
      </geometry>
    </collision>
  </link>

  <link name="arm2_v4_1">
    <inertial>
      <origin xyz="-4.1454899601944815e-09 -0.019999996010484102 0.24789197465992951" rpy="0 0 0"/>
      <mass value="0.773680395029224"/>
      <inertia ixx="0.0" iyy="0.0" izz="0.0" ixy="0.0" iyz="0.0" ixz="0.0"/>
    </inertial>
    <visual>
      <origin xyz="-0.0 -0.02 -0.78" rpy="0 0 0"/>
      <geometry>
        <mesh filename="package://robotarm_description/meshes/arm2_v4_1.stl" scale="0.001 0.001 0.001"/>
      </geometry>
      <material name="steel_satin"/>
    </visual>
    <collision>
      <origin xyz="-0.0 -0.02 -0.78" rpy="0 0 0"/>
      <geometry>
        <mesh filename="package://robotarm_description/meshes/arm2_v4_1.stl" scale="0.001 0.001 0.001"/>
      </geometry>
    </collision>
  </link>

  <link name="arm1_v7_3">
    <inertial>
      <origin xyz="-1.6689085668986083e-11 -0.019999999984820285 0.24789191274178002" rpy="0 0 0"/>
      <mass value="0.773672481443835"/>
      <inertia ixx="0.0" iyy="0.0" izz="0.0" ixy="0.0" iyz="0.0" ixz="0.0"/>
    </inertial>
    <visual>
      <origin xyz="0.0 -0.02 -0.26" rpy="0 0 0"/>
      <geometry>
        <mesh filename="package://robotarm_description/meshes/arm1_v7_3.stl" scale="0.001 0.001 0.001"/>
      </geometry>
      <material name="steel_satin"/>
    </visual>
    <collision>
      <origin xyz="0.0 -0.02 -0.26" rpy="0 0 0"/>
      <geometry>
        <mesh filename="package://robotarm_description/meshes/arm1_v7_3.stl" scale="0.001 0.001 0.001"/>
      </geometry>
    </collision>
  </link>

  <link name="end_joint_v4_2">
    <inertial>
      <origin xyz="-6.05770520933277e-09 -0.019999974177698512 0.06669706204392978" rpy="0 0 0"/>
      <mass value="0.634057744620065"/>
      <inertia ixx="0.0" iyy="0.0" izz="0.0" ixy="0.0" iyz="0.0" ixz="0.0"/>
    </inertial>
    <visual>
      <origin xyz="0.0 -0.02 -1.47" rpy="0 0 0"/>
      <geometry>
        <mesh filename="package://robotarm_description/meshes/end_joint_v4_2.stl" scale="0.001 0.001 0.001"/>
      </geometry>
      <material name="steel_satin"/>
    </visual>
    <collision>
      <origin xyz="0.0 -0.02 -1.47" rpy="0 0 0"/>
      <geometry>
        <mesh filename="package://robotarm_description/meshes/end_joint_v4_2.stl" scale="0.001 0.001 0.001"/>
      </geometry>
    </collision>
  </link>

  <link name="double_joint_v4_2">
    <inertial>
      <origin xyz="0.019999988316214277 -1.4664186026303041e-08 0.06991739176071521" rpy="0 0 0"/>
      <mass value="0.194863507637308"/>
      <inertia ixx="0.0" iyy="0.0" izz="0.0" ixy="0.0" iyz="0.0" ixz="0.0"/>
    </inertial>
    <visual>
      <origin xyz="0.02 -0.0 -1.3" rpy="0 0 0"/>
      <geometry>
        <mesh filename="package://robotarm_description/meshes/double_joint_v4_2.stl" scale="0.001 0.001 0.001"/>
      </geometry>
      <material name="steel_satin"/>
    </visual>
    <collision>
      <origin xyz="0.02 -0.0 -1.3" rpy="0 0 0"/>
      <geometry>
        <mesh filename="package://robotarm_description/meshes/double_joint_v4_2.stl" scale="0.001 0.001 0.001"/>
      </geometry>
    </collision>
  </link>

  <joint name="Slider" type="prismatic">
    <origin xyz="0.0 0.0 0.0" rpy="0 0 0"/>
    <parent link="base_link"/>
    <child link="arm_v2_1"/>
    <axis xyz="0.0 -0.0 1.0"/>
    <limit upper="0.2" lower="0.0" effort="100" velocity="100"/>
  </joint>

  <transmission name="slider_tran">
    <type>transmission_interface/SimpleTransmission</type>
    <joint name="Slider">
      <hardwareInterface>hardware_interface/PositionJointInterface</hardwareInterface>
    </joint>
    <actuator name="slider_motor">
      <hardwareInterface>hardware_interface/PositionJointInterface</hardwareInterface>
      <mechanicalReduction>1</mechanicalReduction>
    </actuator>
  </transmission>

  <joint name="Rev2" type="revolute">
    <origin xyz="0.0 0.0 0.52" rpy="0 0 0"/>
    <parent link="arm1_v7_3"/>
    <child link="arm2_v4_1"/>
    <axis xyz="-0.0 1.0 -0.0"/>
    <limit upper="1.570796" lower="-1.570796" effort="100" velocity="100"/>
  </joint>

  <transmission name="rev2_tran">
    <type>transmission_interface/SimpleTransmission</type>
    <joint name="Rev2">
      <hardwareInterface>hardware_interface/PositionJointInterface</hardwareInterface>
    </joint>
    <actuator name="rev2_motor">
      <hardwareInterface>hardware_interface/PositionJointInterface</hardwareInterface>
      <mechanicalReduction>1</mechanicalReduction>
    </actuator>
  </transmission>

  <joint name="Rev1" type="revolute">
    <origin xyz="0.0 0.02 0.26" rpy="0 0 0"/>
    <parent link="arm_v2_1"/>
    <child link="arm1_v7_3"/>
    <axis xyz="-0.0 1.0 -0.0"/>
    <limit upper="1.570796" lower="-1.570796" effort="100" velocity="100"/>
  </joint>

  <transmission name="rev1_tran">
    <type>transmission_interface/SimpleTransmission</type>
    <joint name="Rev1">
      <hardwareInterface>hardware_interface/PositionJointInterface</hardwareInterface>
    </joint>
    <actuator name="rev1_motor">
      <hardwareInterface>hardware_interface/PositionJointInterface</hardwareInterface>
      <mechanicalReduction>1</mechanicalReduction>
    </actuator>
  </transmission>

  <joint name="Rev4" type="revolute">
    <origin xyz="0.02 0.02 0.17" rpy="0 0 0"/>
    <parent link="double_joint_v4_2"/>
    <child link="end_joint_v4_2"/>
    <axis xyz="-0.0 1.0 -0.0"/>
    <limit upper="1.570796" lower="-1.570796" effort="100" velocity="100"/>
  </joint>

  <transmission name="rev4_tran">
    <type>transmission_interface/SimpleTransmission</type>
    <joint name="Rev4">
      <hardwareInterface>hardware_interface/PositionJointInterface</hardwareInterface>
    </joint>
    <actuator name="rev4_motor">
      <hardwareInterface>hardware_interface/PositionJointInterface</hardwareInterface>
      <mechanicalReduction>1</mechanicalReduction>
    </actuator>
  </transmission>

  <joint name="Rev3" type="revolute">
    <origin xyz="-0.02 -0.02 0.52" rpy="0 0 0"/>
    <parent link="arm2_v4_1"/>
    <child link="double_joint_v4_2"/>
    <axis xyz="-1.0 0.0 -0.0"/>
    <limit upper="1.570796" lower="-1.570796" effort="100" velocity="100"/>
  </joint>

  <transmission name="rev3_tran">
    <type>transmission_interface/SimpleTransmission</type>
    <joint name="Rev3">
      <hardwareInterface>hardware_interface/PositionJointInterface</hardwareInterface>
    </joint>
    <actuator name="rev3_motor">
      <hardwareInterface>hardware_interface/PositionJointInterface</hardwareInterface>
      <mechanicalReduction>1</mechanicalReduction>
    </actuator>
  </transmission>

</robot>
